[2025-02-25 21:01:08] - New changes detected, processing...
[2025-02-25 21:01:12] - No run.ipynb found in C:\Users\nicka\compute-farm\machine_4. Going back to listening...
[2025-02-25 21:05:20] - New changes detected, processing...
[2025-02-25 21:05:25] - No run.ipynb found in C:\Users\nicka\compute-farm\machine_4. Going back to listening...
[2025-02-25 21:10:37] - New changes detected, processing...
[2025-02-25 21:20:49] - Exception occurred:
Traceback (most recent call last):
  File "C:\Users\nicka\compute-farm\packages\Lib\site-packages\nbclient\client.py", line 782, in _async_poll_for_reply
    msg = await ensure_async(self.kc.shell_channel.get_msg(timeout=new_timeout))
          ^^^^^^^^^^^^^^^^^^^^^^^^^^^^^^^^^^^^^^^^^^^^^^^^^^^^^^^^^^^^^^^^^^^^^^
  File "C:\Users\nicka\compute-farm\packages\Lib\site-packages\jupyter_core\utils\__init__.py", line 198, in ensure_async
    result = await obj
             ^^^^^^^^^
  File "C:\Users\nicka\compute-farm\packages\Lib\site-packages\jupyter_client\channels.py", line 313, in get_msg
    raise Empty
_queue.Empty

During handling of the above exception, another exception occurred:

Traceback (most recent call last):
  File "C:\Users\nicka\compute-farm\main.py", line 70, in run_notebook
    ep.preprocess(nb, {"metadata": {"path": MACHINE_FOLDER}})
  File "C:\Users\nicka\compute-farm\packages\Lib\site-packages\nbconvert\preprocessors\execute.py", line 103, in preprocess
    self.preprocess_cell(cell, resources, index)
  File "C:\Users\nicka\compute-farm\packages\Lib\site-packages\nbconvert\preprocessors\execute.py", line 124, in preprocess_cell
    cell = self.execute_cell(cell, index, store_history=True)
           ^^^^^^^^^^^^^^^^^^^^^^^^^^^^^^^^^^^^^^^^^^^^^^^^^^
  File "C:\Users\nicka\compute-farm\packages\Lib\site-packages\jupyter_core\utils\__init__.py", line 165, in wrapped
    return loop.run_until_complete(inner)
           ^^^^^^^^^^^^^^^^^^^^^^^^^^^^^^
  File "C:\Program Files\Python312\Lib\asyncio\base_events.py", line 687, in run_until_complete
    return future.result()
           ^^^^^^^^^^^^^^^
  File "C:\Users\nicka\compute-farm\packages\Lib\site-packages\nbclient\client.py", line 1005, in async_execute_cell
    exec_reply = await self.task_poll_for_reply
                 ^^^^^^^^^^^^^^^^^^^^^^^^^^^^^^
  File "C:\Users\nicka\compute-farm\packages\Lib\site-packages\nbclient\client.py", line 806, in _async_poll_for_reply
    error_on_timeout_execute_reply = await self._async_handle_timeout(timeout, cell)
                                     ^^^^^^^^^^^^^^^^^^^^^^^^^^^^^^^^^^^^^^^^^^^^^^^
  File "C:\Users\nicka\compute-farm\packages\Lib\site-packages\nbclient\client.py", line 856, in _async_handle_timeout
    raise CellTimeoutError.error_from_timeout_and_cell(
nbclient.exceptions.CellTimeoutError: A cell timed out while it was being executed, after 600 seconds.
The message was: Cell execution timed out.
Here is a preview of the cell contents:
-------------------
['from gan10 import GAN10', '', '', 'for asset_name in returns_df.columns:', '    print(f"Training WGAN for {asset_name}...")']
...
['    ', '    # Train WGAN for this asset', '    gan.train()', '    ', '    print(f"Finished training WGAN for {asset_name}.\\n")']
-------------------


[2025-02-25 21:20:49] - Moved notebook to C:\Users\nicka\compute-farm\results\run_4_error_20250225_212049.ipynb (status: error, includes outputs)
[2025-02-25 21:21:24] - New changes detected, processing...
[2025-02-25 21:24:14] - New changes detected, processing...
[2025-02-25 21:24:14] - Exception occurred:
Traceback (most recent call last):
  File "C:\Users\nicka\compute-farm\main.py", line 41, in pull_repo
    subprocess.run(["git", "pull", "origin", BRANCH], cwd=REPO_DIR, check=True)
  File "C:\Program Files\Python312\Lib\subprocess.py", line 571, in run
    raise CalledProcessError(retcode, process.args,
subprocess.CalledProcessError: Command '['git', 'pull', 'origin', 'main']' returned non-zero exit status 128.

[2025-02-25 21:24:16] - No run.ipynb found in C:\Users\nicka\compute-farm\machine_4. Going back to listening...
[2025-02-25 21:27:50] - New changes detected, processing...
[2025-02-25 21:27:54] - No run.ipynb found in C:\Users\nicka\compute-farm\machine_4. Going back to listening...
[2025-02-25 21:29:59] - New changes detected, processing...
[2025-02-25 21:30:03] - No run.ipynb found in C:\Users\nicka\compute-farm\machine_4. Going back to listening...
[2025-02-25 21:34:13] - New changes detected, processing...
[2025-02-25 21:44:24] - Exception occurred:
Traceback (most recent call last):
  File "C:\Users\nicka\compute-farm\packages\Lib\site-packages\nbclient\client.py", line 782, in _async_poll_for_reply
    msg = await ensure_async(self.kc.shell_channel.get_msg(timeout=new_timeout))
          ^^^^^^^^^^^^^^^^^^^^^^^^^^^^^^^^^^^^^^^^^^^^^^^^^^^^^^^^^^^^^^^^^^^^^^
  File "C:\Users\nicka\compute-farm\packages\Lib\site-packages\jupyter_core\utils\__init__.py", line 198, in ensure_async
    result = await obj
             ^^^^^^^^^
  File "C:\Users\nicka\compute-farm\packages\Lib\site-packages\jupyter_client\channels.py", line 313, in get_msg
    raise Empty
_queue.Empty

During handling of the above exception, another exception occurred:

Traceback (most recent call last):
  File "C:\Users\nicka\compute-farm\main.py", line 70, in run_notebook
    ep = ExecutePreprocessor(timeout=600, kernel_name="python3")
    ^^^^^^^^^^^^^^^^^^^^^^^^^^^^^^^^^^^^^^^^^^^^^^^^^^^^^^^^^
  File "C:\Users\nicka\compute-farm\packages\Lib\site-packages\nbconvert\preprocessors\execute.py", line 103, in preprocess
    self.preprocess_cell(cell, resources, index)
  File "C:\Users\nicka\compute-farm\packages\Lib\site-packages\nbconvert\preprocessors\execute.py", line 124, in preprocess_cell
    cell = self.execute_cell(cell, index, store_history=True)
           ^^^^^^^^^^^^^^^^^^^^^^^^^^^^^^^^^^^^^^^^^^^^^^^^^^
  File "C:\Users\nicka\compute-farm\packages\Lib\site-packages\jupyter_core\utils\__init__.py", line 165, in wrapped
    return loop.run_until_complete(inner)
           ^^^^^^^^^^^^^^^^^^^^^^^^^^^^^^
  File "C:\Program Files\Python312\Lib\asyncio\base_events.py", line 687, in run_until_complete
    return future.result()
           ^^^^^^^^^^^^^^^
  File "C:\Users\nicka\compute-farm\packages\Lib\site-packages\nbclient\client.py", line 1005, in async_execute_cell
    exec_reply = await self.task_poll_for_reply
                 ^^^^^^^^^^^^^^^^^^^^^^^^^^^^^^
  File "C:\Users\nicka\compute-farm\packages\Lib\site-packages\nbclient\client.py", line 806, in _async_poll_for_reply
    error_on_timeout_execute_reply = await self._async_handle_timeout(timeout, cell)
                                     ^^^^^^^^^^^^^^^^^^^^^^^^^^^^^^^^^^^^^^^^^^^^^^^
  File "C:\Users\nicka\compute-farm\packages\Lib\site-packages\nbclient\client.py", line 856, in _async_handle_timeout
    raise CellTimeoutError.error_from_timeout_and_cell(
nbclient.exceptions.CellTimeoutError: A cell timed out while it was being executed, after 600 seconds.
The message was: Cell execution timed out.
Here is a preview of the cell contents:
-------------------
['from gan10 import GAN10', '', '', 'for asset_name in returns_df.columns:', '    print(f"Training WGAN for {asset_name}...")']
...
['    ', '    # Train WGAN for this asset', '    gan.train()', '    ', '    print(f"Finished training WGAN for {asset_name}.\\n")']
-------------------


[2025-02-25 21:44:24] - Moved notebook to C:\Users\nicka\compute-farm\results\run_4_error_20250225_214424.ipynb (status: error, includes outputs)
[2025-02-25 21:44:57] - New changes detected, processing...
[2025-02-25 21:47:59] - Exception occurred:
Traceback (most recent call last):
  File "C:\Users\nicka\compute-farm\main.py", line 41, in pull_repo
    """Pull the latest changes from GitHub and install root dependencies"""
        ^^^^^^^^^^^^^^^^^^^^^^^^^^^^^^^^^^^^^^^^^^^^^^^^^^^^^^^^^^^^^^^^^^^^
  File "C:\Program Files\Python312\Lib\subprocess.py", line 571, in run
    raise CalledProcessError(retcode, process.args,
subprocess.CalledProcessError: Command '['git', 'pull', 'origin', 'main']' returned non-zero exit status 1.

[2025-02-25 21:48:02] - No run.ipynb found in C:\Users\nicka\compute-farm\machine_4. Going back to listening...
