[2025-02-25 20:19:05] - New changes detected, processing...
[2025-02-25 20:19:10] - No run.ipynb found in C:\Users\nicka\compute-farm\machine_3. Going back to listening...
[2025-02-25 20:24:44] - New changes detected, processing...
[2025-02-25 20:24:48] - No run.ipynb found in C:\Users\nicka\compute-farm\machine_3. Going back to listening...
[2025-02-25 20:27:56] - New changes detected, processing...
[2025-02-25 20:34:33] - Notebook execution completed successfully.
[2025-02-25 20:34:33] - Moved notebook to C:\Users\nicka\compute-farm\results\run_3_success_20250225_203433.ipynb (status: success, includes outputs)
[2025-02-25 20:34:36] - Exception occurred:
Traceback (most recent call last):
  File "C:\Users\nicka\compute-farm\main.py", line 119, in push_results
    subprocess.run(["git", "push", "origin", BRANCH], cwd=REPO_DIR, check=True)
  File "C:\Program Files\Python312\Lib\subprocess.py", line 571, in run
    raise CalledProcessError(retcode, process.args,
subprocess.CalledProcessError: Command '['git', 'push', 'origin', 'main']' returned non-zero exit status 1.

[2025-02-25 20:35:11] - New changes detected, processing...
[2025-02-25 20:44:05] - New changes detected, processing...
[2025-02-25 20:44:09] - No run.ipynb found in C:\Users\nicka\compute-farm\machine_3. Going back to listening...
[2025-02-25 21:05:28] - New changes detected, processing...
[2025-02-25 21:05:33] - No run.ipynb found in C:\Users\nicka\compute-farm\machine_3. Going back to listening...
[2025-02-25 21:10:45] - New changes detected, processing...
[2025-02-25 21:20:56] - Exception occurred:
Traceback (most recent call last):
  File "C:\Users\nicka\compute-farm\packages\Lib\site-packages\nbclient\client.py", line 782, in _async_poll_for_reply
    msg = await ensure_async(self.kc.shell_channel.get_msg(timeout=new_timeout))
          ^^^^^^^^^^^^^^^^^^^^^^^^^^^^^^^^^^^^^^^^^^^^^^^^^^^^^^^^^^^^^^^^^^^^^^
  File "C:\Users\nicka\compute-farm\packages\Lib\site-packages\jupyter_core\utils\__init__.py", line 198, in ensure_async
    result = await obj
             ^^^^^^^^^
  File "C:\Users\nicka\compute-farm\packages\Lib\site-packages\jupyter_client\channels.py", line 313, in get_msg
    raise Empty
_queue.Empty

During handling of the above exception, another exception occurred:

Traceback (most recent call last):
  File "C:\Users\nicka\compute-farm\main.py", line 70, in run_notebook
    ep.preprocess(nb, {"metadata": {"path": MACHINE_FOLDER}})
  File "C:\Users\nicka\compute-farm\packages\Lib\site-packages\nbconvert\preprocessors\execute.py", line 103, in preprocess
    self.preprocess_cell(cell, resources, index)
  File "C:\Users\nicka\compute-farm\packages\Lib\site-packages\nbconvert\preprocessors\execute.py", line 124, in preprocess_cell
    cell = self.execute_cell(cell, index, store_history=True)
           ^^^^^^^^^^^^^^^^^^^^^^^^^^^^^^^^^^^^^^^^^^^^^^^^^^
  File "C:\Users\nicka\compute-farm\packages\Lib\site-packages\jupyter_core\utils\__init__.py", line 165, in wrapped
    return loop.run_until_complete(inner)
           ^^^^^^^^^^^^^^^^^^^^^^^^^^^^^^
  File "C:\Program Files\Python312\Lib\asyncio\base_events.py", line 687, in run_until_complete
    return future.result()
           ^^^^^^^^^^^^^^^
  File "C:\Users\nicka\compute-farm\packages\Lib\site-packages\nbclient\client.py", line 1005, in async_execute_cell
    exec_reply = await self.task_poll_for_reply
                 ^^^^^^^^^^^^^^^^^^^^^^^^^^^^^^
  File "C:\Users\nicka\compute-farm\packages\Lib\site-packages\nbclient\client.py", line 806, in _async_poll_for_reply
    error_on_timeout_execute_reply = await self._async_handle_timeout(timeout, cell)
                                     ^^^^^^^^^^^^^^^^^^^^^^^^^^^^^^^^^^^^^^^^^^^^^^^
  File "C:\Users\nicka\compute-farm\packages\Lib\site-packages\nbclient\client.py", line 856, in _async_handle_timeout
    raise CellTimeoutError.error_from_timeout_and_cell(
nbclient.exceptions.CellTimeoutError: A cell timed out while it was being executed, after 600 seconds.
The message was: Cell execution timed out.
Here is a preview of the cell contents:
-------------------
['from gan10 import GAN10', '', '', 'for asset_name in returns_df.columns:', '    print(f"Training WGAN for {asset_name}...")']
...
['    ', '    # Train WGAN for this asset', '    gan.train()', '    ', '    print(f"Finished training WGAN for {asset_name}.\\n")']
-------------------


[2025-02-25 21:20:56] - Moved notebook to C:\Users\nicka\compute-farm\results\run_3_error_20250225_212056.ipynb (status: error, includes outputs)
[2025-02-25 21:21:33] - New changes detected, processing...
[2025-02-25 21:23:09] - Exception occurred:
Traceback (most recent call last):
  File "C:\Users\nicka\compute-farm\main.py", line 41, in pull_repo
    subprocess.run(["git", "pull", "origin", BRANCH], cwd=REPO_DIR, check=True)
  File "C:\Program Files\Python312\Lib\subprocess.py", line 571, in run
    raise CalledProcessError(retcode, process.args,
subprocess.CalledProcessError: Command '['git', 'pull', 'origin', 'main']' returned non-zero exit status 1.

[2025-02-25 21:23:12] - Log file pushed successfully.
[2025-02-25 21:23:12] - No run.ipynb found in C:\Users\nicka\compute-farm\machine_3. Going back to listening...
[2025-02-25 21:23:43] - New changes detected, processing...
[2025-02-25 21:23:47] - No run.ipynb found in C:\Users\nicka\compute-farm\machine_3. Going back to listening...
[2025-02-25 21:25:52] - New changes detected, processing...
[2025-02-25 21:25:57] - No run.ipynb found in C:\Users\nicka\compute-farm\machine_3. Going back to listening...
[2025-02-25 21:26:45] - New changes detected, processing...
[2025-02-25 21:26:49] - No run.ipynb found in C:\Users\nicka\compute-farm\machine_3. Going back to listening...
[2025-02-25 21:30:28] - New changes detected, processing...
[2025-02-25 21:30:32] - No run.ipynb found in C:\Users\nicka\compute-farm\machine_3. Going back to listening...
[2025-02-25 21:34:11] - New changes detected, processing...
[2025-02-25 21:44:22] - Exception occurred:
Traceback (most recent call last):
  File "C:\Users\nicka\compute-farm\packages\Lib\site-packages\nbclient\client.py", line 782, in _async_poll_for_reply
    msg = await ensure_async(self.kc.shell_channel.get_msg(timeout=new_timeout))
          ^^^^^^^^^^^^^^^^^^^^^^^^^^^^^^^^^^^^^^^^^^^^^^^^^^^^^^^^^^^^^^^^^^^^^^
  File "C:\Users\nicka\compute-farm\packages\Lib\site-packages\jupyter_core\utils\__init__.py", line 198, in ensure_async
    result = await obj
             ^^^^^^^^^
  File "C:\Users\nicka\compute-farm\packages\Lib\site-packages\jupyter_client\channels.py", line 313, in get_msg
    raise Empty
_queue.Empty

During handling of the above exception, another exception occurred:

Traceback (most recent call last):
  File "C:\Users\nicka\compute-farm\main.py", line 70, in run_notebook
    ep = ExecutePreprocessor(timeout=600, kernel_name="python3")
    ^^^^^^^^^^^^^^^^^^^^^^^^^^^^^^^^^^^^^^^^^^^^^^^^^^^^^^^^^
  File "C:\Users\nicka\compute-farm\packages\Lib\site-packages\nbconvert\preprocessors\execute.py", line 103, in preprocess
    self.preprocess_cell(cell, resources, index)
  File "C:\Users\nicka\compute-farm\packages\Lib\site-packages\nbconvert\preprocessors\execute.py", line 124, in preprocess_cell
    cell = self.execute_cell(cell, index, store_history=True)
           ^^^^^^^^^^^^^^^^^^^^^^^^^^^^^^^^^^^^^^^^^^^^^^^^^^
  File "C:\Users\nicka\compute-farm\packages\Lib\site-packages\jupyter_core\utils\__init__.py", line 165, in wrapped
    return loop.run_until_complete(inner)
           ^^^^^^^^^^^^^^^^^^^^^^^^^^^^^^
  File "C:\Program Files\Python312\Lib\asyncio\base_events.py", line 687, in run_until_complete
    return future.result()
           ^^^^^^^^^^^^^^^
  File "C:\Users\nicka\compute-farm\packages\Lib\site-packages\nbclient\client.py", line 1005, in async_execute_cell
    exec_reply = await self.task_poll_for_reply
                 ^^^^^^^^^^^^^^^^^^^^^^^^^^^^^^
  File "C:\Users\nicka\compute-farm\packages\Lib\site-packages\nbclient\client.py", line 806, in _async_poll_for_reply
    error_on_timeout_execute_reply = await self._async_handle_timeout(timeout, cell)
                                     ^^^^^^^^^^^^^^^^^^^^^^^^^^^^^^^^^^^^^^^^^^^^^^^
  File "C:\Users\nicka\compute-farm\packages\Lib\site-packages\nbclient\client.py", line 856, in _async_handle_timeout
    raise CellTimeoutError.error_from_timeout_and_cell(
nbclient.exceptions.CellTimeoutError: A cell timed out while it was being executed, after 600 seconds.
The message was: Cell execution timed out.
Here is a preview of the cell contents:
-------------------
['from gan10 import GAN10', '', '', 'for asset_name in returns_df.columns:', '    print(f"Training WGAN for {asset_name}...")']
...
['    ', '    # Train WGAN for this asset', '    gan.train()', '    ', '    print(f"Finished training WGAN for {asset_name}.\\n")']
-------------------


[2025-02-25 21:44:22] - Moved notebook to C:\Users\nicka\compute-farm\results\run_3_error_20250225_214422.ipynb (status: error, includes outputs)
[2025-02-25 21:44:25] - Log file pushed successfully.
[2025-02-25 21:44:56] - New changes detected, processing...
[2025-02-25 21:45:00] - No run.ipynb found in C:\Users\nicka\compute-farm\machine_3. Going back to listening...
[2025-02-25 21:46:03] - New changes detected, processing...
[2025-02-25 21:46:07] - No run.ipynb found in C:\Users\nicka\compute-farm\machine_3. Going back to listening...
[2025-02-25 21:48:13] - New changes detected, processing...
[2025-02-25 21:48:17] - No run.ipynb found in C:\Users\nicka\compute-farm\machine_3. Going back to listening...
[2025-02-25 21:48:49] - New changes detected, processing...
[2025-02-25 21:48:53] - No run.ipynb found in C:\Users\nicka\compute-farm\machine_3. Going back to listening...
[2025-02-25 21:49:56] - New changes detected, processing...
[2025-02-25 21:50:00] - No run.ipynb found in C:\Users\nicka\compute-farm\machine_3. Going back to listening...
