[2025-02-25 20:19:05] - New changes detected, processing...
[2025-02-25 20:19:10] - No run.ipynb found in C:\Users\nicka\compute-farm\machine_3. Going back to listening...
[2025-02-25 20:24:44] - New changes detected, processing...
[2025-02-25 20:24:48] - No run.ipynb found in C:\Users\nicka\compute-farm\machine_3. Going back to listening...
[2025-02-25 20:27:56] - New changes detected, processing...
[2025-02-25 20:34:33] - Notebook execution completed successfully.
[2025-02-25 20:34:33] - Moved notebook to C:\Users\nicka\compute-farm\results\run_3_success_20250225_203433.ipynb (status: success, includes outputs)
[2025-02-25 20:34:36] - Exception occurred:
Traceback (most recent call last):
  File "C:\Users\nicka\compute-farm\main.py", line 119, in push_results
    subprocess.run(["git", "push", "origin", BRANCH], cwd=REPO_DIR, check=True)
  File "C:\Program Files\Python312\Lib\subprocess.py", line 571, in run
    raise CalledProcessError(retcode, process.args,
subprocess.CalledProcessError: Command '['git', 'push', 'origin', 'main']' returned non-zero exit status 1.

[2025-02-25 20:35:11] - New changes detected, processing...
