[2025-02-25 20:00:12] - New changes detected, processing...
[2025-02-25 20:00:23] - Exception occurred:
Traceback (most recent call last):
  File "C:\Users\nicka\compute-farm\main.py", line 70, in run_notebook
    ep.preprocess(nb, {"metadata": {"path": MACHINE_FOLDER}})
  File "C:\Users\nicka\compute-farm\packages\Lib\site-packages\nbconvert\preprocessors\execute.py", line 103, in preprocess
    self.preprocess_cell(cell, resources, index)
  File "C:\Users\nicka\compute-farm\packages\Lib\site-packages\nbconvert\preprocessors\execute.py", line 124, in preprocess_cell
    cell = self.execute_cell(cell, index, store_history=True)
           ^^^^^^^^^^^^^^^^^^^^^^^^^^^^^^^^^^^^^^^^^^^^^^^^^^
  File "C:\Users\nicka\compute-farm\packages\Lib\site-packages\jupyter_core\utils\__init__.py", line 165, in wrapped
    return loop.run_until_complete(inner)
           ^^^^^^^^^^^^^^^^^^^^^^^^^^^^^^
  File "C:\Program Files\Python312\Lib\asyncio\base_events.py", line 687, in run_until_complete
    return future.result()
           ^^^^^^^^^^^^^^^
  File "C:\Users\nicka\compute-farm\packages\Lib\site-packages\nbclient\client.py", line 1062, in async_execute_cell
    await self._check_raise_for_error(cell, cell_index, exec_reply)
  File "C:\Users\nicka\compute-farm\packages\Lib\site-packages\nbclient\client.py", line 918, in _check_raise_for_error
    raise CellExecutionError.from_cell_and_msg(cell, exec_reply_content)
nbclient.exceptions.CellExecutionError: An error occurred while executing the following cell:
------------------
def fetch_data_df():
    # Load the data
    df = pd.read_csv('../../../data/final_daily_returns_asset_classes.csv', index_col=0, parse_dates=True)
    df.index = pd.to_datetime(df.index)
    start_test_date = os.getenv("START_TEST_DATE")
    
    if start_test_date is None:
        raise ValueError("Environment variable 'START_TEST_DATE' is not set.")

    start_test_date = pd.to_datetime(start_test_date)
    
    # Select only the third, sixth, and seventh columns

    # 2, 5, 6
    selected_columns = df.iloc[:, [6]]  # Remember: Python uses 0-based indexing

    pre_test_df = selected_columns[selected_columns.index < start_test_date]
    test_df = selected_columns[selected_columns.index >= start_test_date].iloc[:252]
    
    return pre_test_df, test_df

returns_df, test_returns_df = fetch_data_df()
------------------


[1;31m---------------------------------------------------------------------------[0m
[1;31mFileNotFoundError[0m                         Traceback (most recent call last)
Cell [1;32mIn[2], line 22[0m
[0;32m     18[0m     test_df [38;5;241m=[39m selected_columns[selected_columns[38;5;241m.[39mindex [38;5;241m>[39m[38;5;241m=[39m start_test_date][38;5;241m.[39miloc[:[38;5;241m252[39m]
[0;32m     20[0m     [38;5;28;01mreturn[39;00m pre_test_df, test_df
[1;32m---> 22[0m returns_df, test_returns_df [38;5;241m=[39m [43mfetch_data_df[49m[43m([49m[43m)[49m

Cell [1;32mIn[2], line 3[0m, in [0;36mfetch_data_df[1;34m()[0m
[0;32m      1[0m [38;5;28;01mdef[39;00m[38;5;250m [39m[38;5;21mfetch_data_df[39m():
[0;32m      2[0m     [38;5;66;03m# Load the data[39;00m
[1;32m----> 3[0m     df [38;5;241m=[39m [43mpd[49m[38;5;241;43m.[39;49m[43mread_csv[49m[43m([49m[38;5;124;43m'[39;49m[38;5;124;43m../../../data/final_daily_returns_asset_classes.csv[39;49m[38;5;124;43m'[39;49m[43m,[49m[43m [49m[43mindex_col[49m[38;5;241;43m=[39;49m[38;5;241;43m0[39;49m[43m,[49m[43m [49m[43mparse_dates[49m[38;5;241;43m=[39;49m[38;5;28;43;01mTrue[39;49;00m[43m)[49m
[0;32m      4[0m     df[38;5;241m.[39mindex [38;5;241m=[39m pd[38;5;241m.[39mto_datetime(df[38;5;241m.[39mindex)
[0;32m      5[0m     start_test_date [38;5;241m=[39m os[38;5;241m.[39mgetenv([38;5;124m"[39m[38;5;124mSTART_TEST_DATE[39m[38;5;124m"[39m)

File [1;32m~\compute-farm\packages\Lib\site-packages\pandas\io\parsers\readers.py:1026[0m, in [0;36mread_csv[1;34m(filepath_or_buffer, sep, delimiter, header, names, index_col, usecols, dtype, engine, converters, true_values, false_values, skipinitialspace, skiprows, skipfooter, nrows, na_values, keep_default_na, na_filter, verbose, skip_blank_lines, parse_dates, infer_datetime_format, keep_date_col, date_parser, date_format, dayfirst, cache_dates, iterator, chunksize, compression, thousands, decimal, lineterminator, quotechar, quoting, doublequote, escapechar, comment, encoding, encoding_errors, dialect, on_bad_lines, delim_whitespace, low_memory, memory_map, float_precision, storage_options, dtype_backend)[0m
[0;32m   1013[0m kwds_defaults [38;5;241m=[39m _refine_defaults_read(
[0;32m   1014[0m     dialect,
[0;32m   1015[0m     delimiter,
[1;32m   (...)[0m
[0;32m   1022[0m     dtype_backend[38;5;241m=[39mdtype_backend,
[0;32m   1023[0m )
[0;32m   1024[0m kwds[38;5;241m.[39mupdate(kwds_defaults)
[1;32m-> 1026[0m [38;5;28;01mreturn[39;00m [43m_read[49m[43m([49m[43mfilepath_or_buffer[49m[43m,[49m[43m [49m[43mkwds[49m[43m)[49m

File [1;32m~\compute-farm\packages\Lib\site-packages\pandas\io\parsers\readers.py:620[0m, in [0;36m_read[1;34m(filepath_or_buffer, kwds)[0m
[0;32m    617[0m _validate_names(kwds[38;5;241m.[39mget([38;5;124m"[39m[38;5;124mnames[39m[38;5;124m"[39m, [38;5;28;01mNone[39;00m))
[0;32m    619[0m [38;5;66;03m# Create the parser.[39;00m
[1;32m--> 620[0m parser [38;5;241m=[39m [43mTextFileReader[49m[43m([49m[43mfilepath_or_buffer[49m[43m,[49m[43m [49m[38;5;241;43m*[39;49m[38;5;241;43m*[39;49m[43mkwds[49m[43m)[49m
[0;32m    622[0m [38;5;28;01mif[39;00m chunksize [38;5;129;01mor[39;00m iterator:
[0;32m    623[0m     [38;5;28;01mreturn[39;00m parser

File [1;32m~\compute-farm\packages\Lib\site-packages\pandas\io\parsers\readers.py:1620[0m, in [0;36mTextFileReader.__init__[1;34m(self, f, engine, **kwds)[0m
[0;32m   1617[0m     [38;5;28mself[39m[38;5;241m.[39moptions[[38;5;124m"[39m[38;5;124mhas_index_names[39m[38;5;124m"[39m] [38;5;241m=[39m kwds[[38;5;124m"[39m[38;5;124mhas_index_names[39m[38;5;124m"[39m]
[0;32m   1619[0m [38;5;28mself[39m[38;5;241m.[39mhandles: IOHandles [38;5;241m|[39m [38;5;28;01mNone[39;00m [38;5;241m=[39m [38;5;28;01mNone[39;00m
[1;32m-> 1620[0m [38;5;28mself[39m[38;5;241m.[39m_engine [38;5;241m=[39m [38;5;28;43mself[39;49m[38;5;241;43m.[39;49m[43m_make_engine[49m[43m([49m[43mf[49m[43m,[49m[43m [49m[38;5;28;43mself[39;49m[38;5;241;43m.[39;49m[43mengine[49m[43m)[49m

File [1;32m~\compute-farm\packages\Lib\site-packages\pandas\io\parsers\readers.py:1880[0m, in [0;36mTextFileReader._make_engine[1;34m(self, f, engine)[0m
[0;32m   1878[0m     [38;5;28;01mif[39;00m [38;5;124m"[39m[38;5;124mb[39m[38;5;124m"[39m [38;5;129;01mnot[39;00m [38;5;129;01min[39;00m mode:
[0;32m   1879[0m         mode [38;5;241m+[39m[38;5;241m=[39m [38;5;124m"[39m[38;5;124mb[39m[38;5;124m"[39m
[1;32m-> 1880[0m [38;5;28mself[39m[38;5;241m.[39mhandles [38;5;241m=[39m [43mget_handle[49m[43m([49m
[0;32m   1881[0m [43m    [49m[43mf[49m[43m,[49m
[0;32m   1882[0m [43m    [49m[43mmode[49m[43m,[49m
[0;32m   1883[0m [43m    [49m[43mencoding[49m[38;5;241;43m=[39;49m[38;5;28;43mself[39;49m[38;5;241;43m.[39;49m[43moptions[49m[38;5;241;43m.[39;49m[43mget[49m[43m([49m[38;5;124;43m"[39;49m[38;5;124;43mencoding[39;49m[38;5;124;43m"[39;49m[43m,[49m[43m [49m[38;5;28;43;01mNone[39;49;00m[43m)[49m[43m,[49m
[0;32m   1884[0m [43m    [49m[43mcompression[49m[38;5;241;43m=[39;49m[38;5;28;43mself[39;49m[38;5;241;43m.[39;49m[43moptions[49m[38;5;241;43m.[39;49m[43mget[49m[43m([49m[38;5;124;43m"[39;49m[38;5;124;43mcompression[39;49m[38;5;124;43m"[39;49m[43m,[49m[43m [49m[38;5;28;43;01mNone[39;49;00m[43m)[49m[43m,[49m
[0;32m   1885[0m [43m    [49m[43mmemory_map[49m[38;5;241;43m=[39;49m[38;5;28;43mself[39;49m[38;5;241;43m.[39;49m[43moptions[49m[38;5;241;43m.[39;49m[43mget[49m[43m([49m[38;5;124;43m"[39;49m[38;5;124;43mmemory_map[39;49m[38;5;124;43m"[39;49m[43m,[49m[43m [49m[38;5;28;43;01mFalse[39;49;00m[43m)[49m[43m,[49m
[0;32m   1886[0m [43m    [49m[43mis_text[49m[38;5;241;43m=[39;49m[43mis_text[49m[43m,[49m
[0;32m   1887[0m [43m    [49m[43merrors[49m[38;5;241;43m=[39;49m[38;5;28;43mself[39;49m[38;5;241;43m.[39;49m[43moptions[49m[38;5;241;43m.[39;49m[43mget[49m[43m([49m[38;5;124;43m"[39;49m[38;5;124;43mencoding_errors[39;49m[38;5;124;43m"[39;49m[43m,[49m[43m [49m[38;5;124;43m"[39;49m[38;5;124;43mstrict[39;49m[38;5;124;43m"[39;49m[43m)[49m[43m,[49m
[0;32m   1888[0m [43m    [49m[43mstorage_options[49m[38;5;241;43m=[39;49m[38;5;28;43mself[39;49m[38;5;241;43m.[39;49m[43moptions[49m[38;5;241;43m.[39;49m[43mget[49m[43m([49m[38;5;124;43m"[39;49m[38;5;124;43mstorage_options[39;49m[38;5;124;43m"[39;49m[43m,[49m[43m [49m[38;5;28;43;01mNone[39;49;00m[43m)[49m[43m,[49m
[0;32m   1889[0m [43m[49m[43m)[49m
[0;32m   1890[0m [38;5;28;01massert[39;00m [38;5;28mself[39m[38;5;241m.[39mhandles [38;5;129;01mis[39;00m [38;5;129;01mnot[39;00m [38;5;28;01mNone[39;00m
[0;32m   1891[0m f [38;5;241m=[39m [38;5;28mself[39m[38;5;241m.[39mhandles[38;5;241m.[39mhandle

File [1;32m~\compute-farm\packages\Lib\site-packages\pandas\io\common.py:873[0m, in [0;36mget_handle[1;34m(path_or_buf, mode, encoding, compression, memory_map, is_text, errors, storage_options)[0m
[0;32m    868[0m [38;5;28;01melif[39;00m [38;5;28misinstance[39m(handle, [38;5;28mstr[39m):
[0;32m    869[0m     [38;5;66;03m# Check whether the filename is to be opened in binary mode.[39;00m
[0;32m    870[0m     [38;5;66;03m# Binary mode does not support 'encoding' and 'newline'.[39;00m
[0;32m    871[0m     [38;5;28;01mif[39;00m ioargs[38;5;241m.[39mencoding [38;5;129;01mand[39;00m [38;5;124m"[39m[38;5;124mb[39m[38;5;124m"[39m [38;5;129;01mnot[39;00m [38;5;129;01min[39;00m ioargs[38;5;241m.[39mmode:
[0;32m    872[0m         [38;5;66;03m# Encoding[39;00m
[1;32m--> 873[0m         handle [38;5;241m=[39m [38;5;28;43mopen[39;49m[43m([49m
[0;32m    874[0m [43m            [49m[43mhandle[49m[43m,[49m
[0;32m    875[0m [43m            [49m[43mioargs[49m[38;5;241;43m.[39;49m[43mmode[49m[43m,[49m
[0;32m    876[0m [43m            [49m[43mencoding[49m[38;5;241;43m=[39;49m[43mioargs[49m[38;5;241;43m.[39;49m[43mencoding[49m[43m,[49m
[0;32m    877[0m [43m            [49m[43merrors[49m[38;5;241;43m=[39;49m[43merrors[49m[43m,[49m
[0;32m    878[0m [43m            [49m[43mnewline[49m[38;5;241;43m=[39;49m[38;5;124;43m"[39;49m[38;5;124;43m"[39;49m[43m,[49m
[0;32m    879[0m [43m        [49m[43m)[49m
[0;32m    880[0m     [38;5;28;01melse[39;00m:
[0;32m    881[0m         [38;5;66;03m# Binary mode[39;00m
[0;32m    882[0m         handle [38;5;241m=[39m [38;5;28mopen[39m(handle, ioargs[38;5;241m.[39mmode)

[1;31mFileNotFoundError[0m: [Errno 2] No such file or directory: '../../../data/final_daily_returns_asset_classes.csv'


[2025-02-25 20:00:23] - Moved notebook to C:\Users\nicka\compute-farm\results\run_1_error_20250225_200023.ipynb (status: error, includes outputs)
[2025-02-25 20:00:26] - Log file pushed successfully.
[2025-02-25 20:00:57] - New changes detected, processing...
[2025-02-25 20:01:01] - No run.ipynb found in C:\Users\nicka\compute-farm\machine_1. Going back to listening...
[2025-02-25 20:02:35] - New changes detected, processing...
[2025-02-25 20:02:48] - Exception occurred:
Traceback (most recent call last):
  File "C:\Users\nicka\compute-farm\main.py", line 70, in run_notebook
    ep.preprocess(nb, {"metadata": {"path": MACHINE_FOLDER}})
  File "C:\Users\nicka\compute-farm\packages\Lib\site-packages\nbconvert\preprocessors\execute.py", line 103, in preprocess
    self.preprocess_cell(cell, resources, index)
  File "C:\Users\nicka\compute-farm\packages\Lib\site-packages\nbconvert\preprocessors\execute.py", line 124, in preprocess_cell
    cell = self.execute_cell(cell, index, store_history=True)
           ^^^^^^^^^^^^^^^^^^^^^^^^^^^^^^^^^^^^^^^^^^^^^^^^^^
  File "C:\Users\nicka\compute-farm\packages\Lib\site-packages\jupyter_core\utils\__init__.py", line 165, in wrapped
    return loop.run_until_complete(inner)
           ^^^^^^^^^^^^^^^^^^^^^^^^^^^^^^
  File "C:\Program Files\Python312\Lib\asyncio\base_events.py", line 687, in run_until_complete
    return future.result()
           ^^^^^^^^^^^^^^^
  File "C:\Users\nicka\compute-farm\packages\Lib\site-packages\nbclient\client.py", line 1062, in async_execute_cell
    await self._check_raise_for_error(cell, cell_index, exec_reply)
  File "C:\Users\nicka\compute-farm\packages\Lib\site-packages\nbclient\client.py", line 918, in _check_raise_for_error
    raise CellExecutionError.from_cell_and_msg(cell, exec_reply_content)
nbclient.exceptions.CellExecutionError: An error occurred while executing the following cell:
------------------
from gan5 import GAN5
from gan6 import GAN6
from gan7 import GAN7
from gan8 import GAN8
from gan9 import GAN9
from gan10 import GAN10


for asset_name in returns_df.columns:
    print(f"Training WGAN for {asset_name}...")
    asset_returns = returns_df[asset_name]
    
    # Create WGAN instance for the current asset
    gan = GAN10(asset_returns, asset_name)
    
    # Train WGAN for this asset
    gan.train()
    
    print(f"Finished training WGAN for {asset_name}.\n")

------------------


[1;31m---------------------------------------------------------------------------[0m
[1;31mModuleNotFoundError[0m                       Traceback (most recent call last)
Cell [1;32mIn[6], line 1[0m
[1;32m----> 1[0m [38;5;28;01mfrom[39;00m[38;5;250m [39m[38;5;21;01mgan5[39;00m[38;5;250m [39m[38;5;28;01mimport[39;00m GAN5
[0;32m      2[0m [38;5;28;01mfrom[39;00m[38;5;250m [39m[38;5;21;01mgan6[39;00m[38;5;250m [39m[38;5;28;01mimport[39;00m GAN6
[0;32m      3[0m [38;5;28;01mfrom[39;00m[38;5;250m [39m[38;5;21;01mgan7[39;00m[38;5;250m [39m[38;5;28;01mimport[39;00m GAN7

[1;31mModuleNotFoundError[0m: No module named 'gan5'


[2025-02-25 20:02:48] - Moved notebook to C:\Users\nicka\compute-farm\results\run_1_error_20250225_200248.ipynb (status: error, includes outputs)
[2025-02-25 20:02:51] - Log file pushed successfully.
[2025-02-25 20:03:22] - New changes detected, processing...
[2025-02-25 20:03:26] - No run.ipynb found in C:\Users\nicka\compute-farm\machine_1. Going back to listening...
[2025-02-25 20:03:58] - New changes detected, processing...
[2025-02-25 20:04:48] - Notebook execution completed successfully.
[2025-02-25 20:04:48] - Moved notebook to C:\Users\nicka\compute-farm\results\run_1_success_20250225_200448.ipynb (status: success, includes outputs)
[2025-02-25 20:04:55] - Changes pushed successfully.
[2025-02-25 20:05:26] - New changes detected, processing...
[2025-02-25 20:05:30] - No run.ipynb found in C:\Users\nicka\compute-farm\machine_1. Going back to listening...
[2025-02-25 20:12:15] - New changes detected, processing...
[2025-02-25 20:12:20] - No run.ipynb found in C:\Users\nicka\compute-farm\machine_1. Going back to listening...
[2025-02-25 20:18:34] - New changes detected, processing...
[2025-02-25 20:18:38] - No run.ipynb found in C:\Users\nicka\compute-farm\machine_1. Going back to listening...
[2025-02-25 20:24:53] - New changes detected, processing...
[2025-02-25 20:24:58] - No run.ipynb found in C:\Users\nicka\compute-farm\machine_1. Going back to listening...
[2025-02-25 20:28:05] - New changes detected, processing...
[2025-02-25 20:38:16] - Exception occurred:
Traceback (most recent call last):
  File "C:\Users\nicka\compute-farm\packages\Lib\site-packages\nbclient\client.py", line 782, in _async_poll_for_reply
    msg = await ensure_async(self.kc.shell_channel.get_msg(timeout=new_timeout))
          ^^^^^^^^^^^^^^^^^^^^^^^^^^^^^^^^^^^^^^^^^^^^^^^^^^^^^^^^^^^^^^^^^^^^^^
  File "C:\Users\nicka\compute-farm\packages\Lib\site-packages\jupyter_core\utils\__init__.py", line 198, in ensure_async
    result = await obj
             ^^^^^^^^^
  File "C:\Users\nicka\compute-farm\packages\Lib\site-packages\jupyter_client\channels.py", line 313, in get_msg
    raise Empty
_queue.Empty

During handling of the above exception, another exception occurred:

Traceback (most recent call last):
  File "C:\Users\nicka\compute-farm\main.py", line 70, in run_notebook
    ep.preprocess(nb, {"metadata": {"path": MACHINE_FOLDER}})
  File "C:\Users\nicka\compute-farm\packages\Lib\site-packages\nbconvert\preprocessors\execute.py", line 103, in preprocess
    self.preprocess_cell(cell, resources, index)
  File "C:\Users\nicka\compute-farm\packages\Lib\site-packages\nbconvert\preprocessors\execute.py", line 124, in preprocess_cell
    cell = self.execute_cell(cell, index, store_history=True)
           ^^^^^^^^^^^^^^^^^^^^^^^^^^^^^^^^^^^^^^^^^^^^^^^^^^
  File "C:\Users\nicka\compute-farm\packages\Lib\site-packages\jupyter_core\utils\__init__.py", line 165, in wrapped
    return loop.run_until_complete(inner)
           ^^^^^^^^^^^^^^^^^^^^^^^^^^^^^^
  File "C:\Program Files\Python312\Lib\asyncio\base_events.py", line 687, in run_until_complete
    return future.result()
           ^^^^^^^^^^^^^^^
  File "C:\Users\nicka\compute-farm\packages\Lib\site-packages\nbclient\client.py", line 1005, in async_execute_cell
    exec_reply = await self.task_poll_for_reply
                 ^^^^^^^^^^^^^^^^^^^^^^^^^^^^^^
  File "C:\Users\nicka\compute-farm\packages\Lib\site-packages\nbclient\client.py", line 806, in _async_poll_for_reply
    error_on_timeout_execute_reply = await self._async_handle_timeout(timeout, cell)
                                     ^^^^^^^^^^^^^^^^^^^^^^^^^^^^^^^^^^^^^^^^^^^^^^^
  File "C:\Users\nicka\compute-farm\packages\Lib\site-packages\nbclient\client.py", line 856, in _async_handle_timeout
    raise CellTimeoutError.error_from_timeout_and_cell(
nbclient.exceptions.CellTimeoutError: A cell timed out while it was being executed, after 600 seconds.
The message was: Cell execution timed out.
Here is a preview of the cell contents:
-------------------
['from gan10 import GAN10', '', 'for asset_name in returns_df.columns:', '    print(f"Training WGAN for {asset_name}...")', '    asset_returns = returns_df[asset_name]']
...
['    ', '    # Train WGAN for this asset', '    gan.train()', '    ', '    print(f"Finished training WGAN for {asset_name}.\\n")']
-------------------


[2025-02-25 20:38:16] - Moved notebook to C:\Users\nicka\compute-farm\results\run_1_error_20250225_203816.ipynb (status: error, includes outputs)
[2025-02-25 20:43:37] - New changes detected, processing...
[2025-02-25 20:43:41] - No run.ipynb found in C:\Users\nicka\compute-farm\machine_1. Going back to listening...
[2025-02-25 21:05:29] - New changes detected, processing...
[2025-02-25 21:05:33] - No run.ipynb found in C:\Users\nicka\compute-farm\machine_1. Going back to listening...
[2025-02-25 21:10:45] - New changes detected, processing...
[2025-02-25 21:19:55] - Notebook execution completed successfully.
[2025-02-25 21:19:55] - Moved notebook to C:\Users\nicka\compute-farm\results\run_1_success_20250225_211955.ipynb (status: success, includes outputs)
[2025-02-25 21:20:04] - Changes pushed successfully.
[2025-02-25 21:20:36] - New changes detected, processing...
[2025-02-25 21:20:40] - No run.ipynb found in C:\Users\nicka\compute-farm\machine_1. Going back to listening...
[2025-02-25 21:23:16] - New changes detected, processing...
[2025-02-25 21:23:20] - No run.ipynb found in C:\Users\nicka\compute-farm\machine_1. Going back to listening...
[2025-02-25 21:25:56] - New changes detected, processing...
[2025-02-25 21:26:01] - No run.ipynb found in C:\Users\nicka\compute-farm\machine_1. Going back to listening...
[2025-02-25 21:27:03] - New changes detected, processing...
[2025-02-25 21:27:08] - No run.ipynb found in C:\Users\nicka\compute-farm\machine_1. Going back to listening...
[2025-02-25 21:30:04] - New changes detected, processing...
[2025-02-25 21:30:08] - No run.ipynb found in C:\Users\nicka\compute-farm\machine_1. Going back to listening...
[2025-02-25 21:34:17] - New changes detected, processing...
[2025-02-25 21:44:28] - Exception occurred:
Traceback (most recent call last):
  File "C:\Users\nicka\compute-farm\packages\Lib\site-packages\nbclient\client.py", line 782, in _async_poll_for_reply
    msg = await ensure_async(self.kc.shell_channel.get_msg(timeout=new_timeout))
          ^^^^^^^^^^^^^^^^^^^^^^^^^^^^^^^^^^^^^^^^^^^^^^^^^^^^^^^^^^^^^^^^^^^^^^
  File "C:\Users\nicka\compute-farm\packages\Lib\site-packages\jupyter_core\utils\__init__.py", line 198, in ensure_async
    result = await obj
             ^^^^^^^^^
  File "C:\Users\nicka\compute-farm\packages\Lib\site-packages\jupyter_client\channels.py", line 313, in get_msg
    raise Empty
_queue.Empty

During handling of the above exception, another exception occurred:

Traceback (most recent call last):
  File "C:\Users\nicka\compute-farm\main.py", line 73, in run_notebook
    ep.preprocess(nb, {"metadata": {"path": MACHINE_FOLDER}})
  File "C:\Users\nicka\compute-farm\packages\Lib\site-packages\nbconvert\preprocessors\execute.py", line 103, in preprocess
    self.preprocess_cell(cell, resources, index)
  File "C:\Users\nicka\compute-farm\packages\Lib\site-packages\nbconvert\preprocessors\execute.py", line 124, in preprocess_cell
    cell = self.execute_cell(cell, index, store_history=True)
           ^^^^^^^^^^^^^^^^^^^^^^^^^^^^^^^^^^^^^^^^^^^^^^^^^^
  File "C:\Users\nicka\compute-farm\packages\Lib\site-packages\jupyter_core\utils\__init__.py", line 165, in wrapped
    return loop.run_until_complete(inner)
           ^^^^^^^^^^^^^^^^^^^^^^^^^^^^^^
  File "C:\Program Files\Python312\Lib\asyncio\base_events.py", line 687, in run_until_complete
    return future.result()
           ^^^^^^^^^^^^^^^
  File "C:\Users\nicka\compute-farm\packages\Lib\site-packages\nbclient\client.py", line 1005, in async_execute_cell
    exec_reply = await self.task_poll_for_reply
                 ^^^^^^^^^^^^^^^^^^^^^^^^^^^^^^
  File "C:\Users\nicka\compute-farm\packages\Lib\site-packages\nbclient\client.py", line 806, in _async_poll_for_reply
    error_on_timeout_execute_reply = await self._async_handle_timeout(timeout, cell)
                                     ^^^^^^^^^^^^^^^^^^^^^^^^^^^^^^^^^^^^^^^^^^^^^^^
  File "C:\Users\nicka\compute-farm\packages\Lib\site-packages\nbclient\client.py", line 856, in _async_handle_timeout
    raise CellTimeoutError.error_from_timeout_and_cell(
nbclient.exceptions.CellTimeoutError: A cell timed out while it was being executed, after 600 seconds.
The message was: Cell execution timed out.
Here is a preview of the cell contents:
-------------------
['from gan10 import GAN10', '', '', 'for asset_name in returns_df.columns:', '    print(f"Training WGAN for {asset_name}...")']
...
['    ', '    # Train WGAN for this asset', '    gan.train()', '    ', '    print(f"Finished training WGAN for {asset_name}.\\n")']
-------------------


[2025-02-25 21:44:28] - Moved notebook to C:\Users\nicka\compute-farm\results\run_1_error_20250225_214428.ipynb (status: error, includes outputs)
[2025-02-25 21:45:02] - New changes detected, processing...
[2025-02-25 21:45:42] - Exception occurred:
Traceback (most recent call last):
  File "C:\Users\nicka\compute-farm\main.py", line 44, in pull_repo
    subprocess.run(["git", "pull", "origin", BRANCH], cwd=REPO_DIR, check=True)
  File "C:\Program Files\Python312\Lib\subprocess.py", line 571, in run
    raise CalledProcessError(retcode, process.args,
subprocess.CalledProcessError: Command '['git', 'pull', 'origin', 'main']' returned non-zero exit status 1.

[2025-02-25 21:45:44] - Log file pushed successfully.
[2025-02-25 21:45:44] - No run.ipynb found in C:\Users\nicka\compute-farm\machine_1. Going back to listening...
[2025-02-25 21:46:15] - New changes detected, processing...
[2025-02-25 21:46:20] - No run.ipynb found in C:\Users\nicka\compute-farm\machine_1. Going back to listening...
[2025-02-25 21:54:49] - New changes detected, processing...
[2025-02-25 21:54:53] - No run.ipynb found in C:\Users\nicka\compute-farm\machine_1. Going back to listening...
[2025-02-25 22:47:50] - New changes detected, processing...
[2025-02-25 23:41:19] - Notebook execution completed successfully.
[2025-02-25 23:41:19] - Moved notebook to C:\Users\nicka\compute-farm\results\run_1_success_20250225_234119.ipynb (status: success, includes outputs)
[2025-02-25 23:41:22] - Waiting 99 seconds before pushing to avoid conflicts.
[2025-02-25 23:43:01] - Git push failed (attempt 1): Command '['git', 'pull', '--rebase', 'origin', 'main']' returned non-zero exit status 128.
[2025-02-25 23:43:01] - Retrying push after 82 seconds...
[2025-02-25 23:44:23] - Waiting 105 seconds before pushing to avoid conflicts.
[2025-02-25 23:46:08] - Git push failed (attempt 2): Command '['git', 'pull', '--rebase', 'origin', 'main']' returned non-zero exit status 128.
[2025-02-25 23:46:08] - Retrying push after 84 seconds...
[2025-02-25 23:47:33] - Waiting 152 seconds before pushing to avoid conflicts.
[2025-02-25 23:50:05] - Git push failed (attempt 3): Command '['git', 'pull', '--rebase', 'origin', 'main']' returned non-zero exit status 128.
[2025-02-25 23:50:05] - Max retries reached. Skipping Git push.
[2025-02-25 23:50:37] - New changes detected, processing...
[2025-02-26 10:39:11] - New changes detected, processing...
[2025-02-26 10:39:16] - No run.ipynb found in C:\Users\nicka\compute-farm\machine_1. Going back to listening...
[2025-02-26 10:41:20] - New changes detected, processing...
[2025-02-26 11:21:05] - Notebook execution completed successfully.
[2025-02-26 11:21:05] - Moved notebook to C:\Users\nicka\compute-farm\results\run_1_success_20250226_112105.ipynb (status: success, includes outputs)
